Workbook
Name Slicer_Business_Unit: #N/A
Name Slicer_Country: #N/A
Name Slicer_Department: #N/A
Name Slicer_Employee_Status: #N/A

Sheet tbl-employees
A1: EEID | B1: Full Name | C1: Job Title | D1: Department | E1: Business Unit | F1: Gender | G1: Ethnicity | H1: Age | I1: Hire Date | J1: Annual Salary | K1: Bonus % | L1: Country | M1: City | N1: Exit Date | O1: Bonus Amount | P1: Total Compensation | Q1: Employee Status | R1: Tenure | S1: Age Band
A2: E02387 | B2: Emily Davis | C2: Sr. Manger | D2: IT | E2: Research & Development | F2: Female | G2: Black | H2: 55 | I2: 42468 | J2: 141604 | K2: 0.15 | L2: United States | M2: Seattle | N2: 44485 | O2: =J2*K2 -> 21240.6 | P2: =Table1[[#This Row],[Annual Salary]]+Table1[[#This Row],[Bonus Amount]] -> 162844.6 | Q2: =IF(Table1[[#This Row],[Exit Date]]="", "Active","Exited") -> Exited | R2: =IFERROR(DATEDIF(Table1[[#This Row],[Hire Date]],IF(Table1[[#This Row],[Exit Date]]="",TODAY(),Table1[[#This Row],[Exit Date]]),"Y"),"") -> 5 | S2: {=_xlfn.IFS(Table1[[#This Row],[Age]]<30,"Under 30",Table1[[#This Row],[Age]]<=40,"30-40",Table1[[#This Row],[Age]]<50,"41-50",TRUE,"50+")} -> 50+
A3: E04105 | B3: Theodore Dinh | C3: Technical Architect | D3: IT | E3: Manufacturing | F3: Male | G3: Asian | H3: 59 | I3: 35763 | J3: 99975 | K3: 0 | L3: China | M3: Chongqing | O3: =J3*K3 -> 0 | P3: =Table1[[#This Row],[Annual Salary]]+Table1[[#This Row],[Bonus Amount]] -> 99975 | Q3: =IF(Table1[[#This Row],[Exit Date]]="", "Active","Exited") -> Active | R3: =IFERROR(DATEDIF(Table1[[#This Row],[Hire Date]],IF(Table1[[#This Row],[Exit Date]]="",TODAY(),Table1[[#This Row],[Exit Date]]),"Y"),"") -> 28 | S3: {=_xlfn.IFS(Table1[[#This Row],[Age]]<30,"Under 30",Table1[[#This Row],[Age]]<=40,"30-40",Table1[[#This Row],[Age]]<50,"41-50",TRUE,"50+")} -> 50+
A4: E02572 | B4: Luna Sanders | C4: Director | D4: Finance | E4: Speciality Products | F4: Female | G4: Caucasian | H4: 50 | I4: 39016 | J4: 163099 | K4: 0.2 | L4: United States | M4: Chicago | O4: =J4*K4 -> 32619.8 | P4: =Table1[[#This Row],[Annual Salary]]+Table1[[#This Row],[Bonus Amount]] -> 195718.8 | Q4: =IF(Table1[[#This Row],[Exit Date]]="", "Active","Exited") -> Active | R4: =IFERROR(DATEDIF(Table1[[#This Row],[Hire Date]],IF(Table1[[#This Row],[Exit Date]]="",TODAY(),Table1[[#This Row],[Exit Date]]),"Y"),"") -> 19 | S4: {=_xlfn.IFS(Table1[[#This Row],[Age]]<30,"Under 30",Table1[[#This Row],[Age]]<=40,"30-40",Table1[[#This Row],[Age]]<50,"41-50",TRUE,"50+")} -> 50+
A5: E02832 | B5: Penelope Jordan | C5: Computer Systems Manager | D5: IT | E5: Manufacturing | F5: Female | G5: Caucasian | H5: 26 | I5: 43735 | J5: 84913 | K5: 0.07 | L5: United States | M5: Chicago | O5: =J5*K5 -> 5943.91 | P5: =Table1[[#This Row],[Annual Salary]]+Table1[[#This Row],[Bonus Amount]] -> 90856.91 | Q5: =IF(Table1[[#This Row],[Exit Date]]="", "Active","Exited") -> Active | R5: =IFERROR(DATEDIF(Table1[[#This Row],[Hire Date]],IF(Table1[[#This Row],[Exit Date]]="",TODAY(),Table1[[#This Row],[Exit Date]]),"Y"),"") -> 6 | S5: {=_xlfn.IFS(Table1[[#This Row],[Age]]<30,"Under 30",Table1[[#This Row],[Age]]<=40,"30-40",Table1[[#This Row],[Age]]<50,"41-50",TRUE,"50+")} -> Under 30
A6: E01639 | B6: Austin Vo | C6: Sr. Analyst | D6: Finance | E6: Manufacturing | F6: Male | G6: Asian | H6: 55 | I6: 35023 | J6: 95409 | K6: 0 | L6: United States | M6: Phoenix | O6: =J6*K6 -> 0 | P6: =Table1[[#This Row],[Annual Salary]]+Table1[[#This Row],[Bonus Amount]] -> 95409 | Q6: =IF(Table1[[#This Row],[Exit Date]]="", "Active","Exited") -> Active | R6: =IFERROR(DATEDIF(Table1[[#This Row],[Hire Date]],IF(Table1[[#This Row],[Exit Date]]="",TODAY(),Table1[[#This Row],[Exit Date]]),"Y"),"") -> 30 | S6: {=_xlfn.IFS(Table1[[#This Row],[Age]]<30,"Under 30",Table1[[#This Row],[Age]]<=40,"30-40",Table1[[#This Row],[Age]]<50,"41-50",TRUE,"50+")} -> 50+
A7: E00644 | B7: Joshua Gupta | C7: Account Representative | D7: Sales | E7: Corporate | F7: Male | G7: Asian | H7: 57 | I7: 42759 | J7: 50994 | K7: 0 | L7: China | M7: Chongqing | O7: =J7*K7 -> 0 | P7: =Table1[[#This Row],[Annual Salary]]+Table1[[#This Row],[Bonus Amount]] -> 50994 | Q7: =IF(Table1[[#This Row],[Exit Date]]="", "Active","Exited") -> Active | R7: =IFERROR(DATEDIF(Table1[[#This Row],[Hire Date]],IF(Table1[[#This Row],[Exit Date]]="",TODAY(),Table1[[#This Row],[Exit Date]]),"Y"),"") -> 9 | S7: {=_xlfn.IFS(Table1[[#This Row],[Age]]<30,"Under 30",Table1[[#This Row],[Age]]<=40,"30-40",Table1[[#This Row],[Age]]<50,"41-50",TRUE,"50+")} -> 50+
A8: E01550 | B8: Ruby Barnes | C8: Manager | D8: IT | E8: Corporate | F8: Female | G8: Caucasian | H8: 27 | I8: 44013 | J8: 119746 | K8: 0.1 | L8: United States | M8: Phoenix | O8: =J8*K8 -> 11974.6 | P8: =Table1[[#This Row],[Annual Salary]]+Table1[[#This Row],[Bonus Amount]] -> 131720.6 | Q8: =IF(Table1[[#This Row],[Exit Date]]="", "Active","Exited") -> Active | R8: =IFERROR(DATEDIF(Table1[[#This Row],[Hire Date]],IF(Table1[[#This Row],[Exit Date]]="",TODAY(),Table1[[#This Row],[Exit Date]]),"Y"),"") -> 5 | S8: {=_xlfn.IFS(Table1[[#This Row],[Age]]<30,"Under 30",Table1[[#This Row],[Age]]<=40,"30-40",Table1[[#This Row],[Age]]<50,"41-50",TRUE,"50+")} -> Under 30
A9: E04332 | B9: Luke Martin | C9: Analyst | D9: Finance | E9: Manufacturing | F9: Male | G9: Black | H9: 25 | I9: 43967 | J9: 41336 | K9: 0 | L9: United States | M9: Miami | N9: 44336 | O9: =J9*K9 -> 0 | P9: =Table1[[#This Row],[Annual Salary]]+Table1[[#This Row],[Bonus Amount]] -> 41336 | Q9: =IF(Table1[[#This Row],[Exit Date]]="", "Active","Exited") -> Exited | R9: =IFERROR(DATEDIF(Table1[[#This Row],[Hire Date]],IF(Table1[[#This Row],[Exit Date]]="",TODAY(),Table1[[#This Row],[Exit Date]]),"Y"),"") -> 1 | S9: {=_xlfn.IFS(Table1[[#This Row],[Age]]<30,"Under 30",Table1[[#This Row],[Age]]<=40,"30-40",Table1[[#This Row],[Age]]<50,"41-50",TRUE,"50+")} -> Under 30
A10: E04533 | B10: Easton Bailey | C10: Manager | D10: Accounting | E10: Manufacturing | F10: Male | G10: Caucasian | H10: 29 | I10: 43490 | J10: 113527 | K10: 0.06 | L10: United States | M10: Austin | O10: =J10*K10 -> 6811.62 | P10: =Table1[[#This Row],[Annual Salary]]+Table1[[#This Row],[Bonus Amount]] -> 120338.62 | Q10: =IF(Table1[[#This Row],[Exit Date]]="", "Active","Exited") -> Active | R10: =IFERROR(DATEDIF(Table1[[#This Row],[Hire Date]],IF(Table1[[#This Row],[Exit Date]]="",TODAY(),Table1[[#This Row],[Exit Date]]),"Y"),"") -> 7 | S10: {=_xlfn.IFS(Table1[[#This Row],[Age]]<30,"Under 30",Table1[[#This Row],[Age]]<=40,"30-40",Table1[[#This Row],[Age]]<50,"41-50",TRUE,"50+")} -> Under 30
A11: E03838 | B11: Madeline Walker | C11: Sr. Analyst | D11: Finance | E11: Speciality Products | F11: Female | G11: Caucasian | H11: 34 | I11: 43264 | J11: 77203 | K11: 0 | L11: United States | M11: Chicago | O11: =J11*K11 -> 0 | P11: =Table1[[#This Row],[Annual Salary]]+Table1[[#This Row],[Bonus Amount]] -> 77203 | Q11: =IF(Table1[[#This Row],[Exit Date]]="", "Active","Exited") -> Active | R11: =IFERROR(DATEDIF(Table1[[#This Row],[Hire Date]],IF(Table1[[#This Row],[Exit Date]]="",TODAY(),Table1[[#This Row],[Exit Date]]),"Y"),"") -> 7 | S11: {=_xlfn.IFS(Table1[[#This Row],[Age]]<30,"Under 30",Table1[[#This Row],[Age]]<=40,"30-40",Table1[[#This Row],[Age]]<50,"41-50",TRUE,"50+")} -> 30-40
A12: E00591 | B12: Savannah Ali | C12: Sr. Manger | D12: Human Resources | E12: Manufacturing | F12: Female | G12: Asian | H12: 36 | I12: 39855 | J12: 157333 | K12: 0.15 | L12: United States | M12: Miami | O12: =J12*K12 -> 23599.95 | P12: =Table1[[#This Row],[Annual Salary]]+Table1[[#This Row],[Bonus Amount]] -> 180932.95 | Q12: =IF(Table1[[#This Row],[Exit Date]]="", "Active","Exited") -> Active | R12: =IFERROR(DATEDIF(Table1[[#This Row],[Hire Date]],IF(Table1[[#This Row],[Exit Date]]="",TODAY(),Table1[[#This Row],[Exit Date]]),"Y"),"") -> 17 | S12: {=_xlfn.IFS(Table1[[#This Row],[Age]]<30,"Under 30",Table1[[#This Row],[Age]]<=40,"30-40",Table1[[#This Row],[Age]]<50,"41-50",TRUE,"50+")} -> 30-40
A13: E03344 | B13: Camila Rogers | C13: Controls Engineer | D13: Engineering | E13: Speciality Products | F13: Female | G13: Caucasian | H13: 27 | I13: 44490 | J13: 109851 | K13: 0 | L13: United States | M13: Seattle | O13: =J13*K13 -> 0 | P13: =Table1[[#This Row],[Annual Salary]]+Table1[[#This Row],[Bonus Amount]] -> 109851 | Q13: =IF(Table1[[#This Row],[Exit Date]]="", "Active","Exited") -> Active | R13: =IFERROR(DATEDIF(Table1[[#This Row],[Hire Date]],IF(Table1[[#This Row],[Exit Date]]="",TODAY(),Table1[[#This Row],[Exit Date]]),"Y"),"") -> 4 | S13: {=_xlfn.IFS(Table1[[#This Row],[Age]]<30,"Under 30",Table1[[#This Row],[Age]]<=40,"30-40",Table1[[#This Row],[Age]]<50,"41-50",TRUE,"50+")} -> Under 30
A14: E00530 | B14: Eli Jones | C14: Manager | D14: Human Resources | E14: Manufacturing | F14: Male | G14: Caucasian | H14: 59 | I14: 36233 | J14: 105086 | K14: 0.09 | L14: United States | M14: Austin | O14: =J14*K14 -> 9457.74 | P14: =Table1[[#This Row],[Annual Salary]]+Table1[[#This Row],[Bonus Amount]] -> 114543.74 | Q14: =IF(Table1[[#This Row],[Exit Date]]="", "Active","Exited") -> Active | R14: =IFERROR(DATEDIF(Table1[[#This Row],[Hire Date]],IF(Table1[[#This Row],[Exit Date]]="",TODAY(),Table1[[#This Row],[Exit Date]]),"Y"),"") -> 27 | S14: {=_xlfn.IFS(Table1[[#This Row],[Age]]<30,"Under 30",Table1[[#This Row],[Age]]<=40,"30-40",Table1[[#This Row],[Age]]<50,"41-50",TRUE,"50+")} -> 50+
A15: E04239 | B15: Everleigh Ng | C15: Sr. Manger | D15: Finance | E15: Research & Development | F15: Female | G15: Asian | H15: 51 | I15: 44357 | J15: 146742 | K15: 0.1 | L15: China | M15: Shanghai | O15: =J15*K15 -> 14674.2 | P15: =Table1[[#This Row],[Annual Salary]]+Table1[[#This Row],[Bonus Amount]] -> 161416.2 | Q15: =IF(Table1[[#This Row],[Exit Date]]="", "Active","Exited") -> Active | R15: =IFERROR(DATEDIF(Table1[[#This Row],[Hire Date]],IF(Table1[[#This Row],[Exit Date]]="",TODAY(),Table1[[#This Row],[Exit Date]]),"Y"),"") -> 4 | S15: {=_xlfn.IFS(Table1[[#This Row],[Age]]<30,"Under 30",Table1[[#This Row],[Age]]<=40,"30-40",Table1[[#This Row],[Age]]<50,"41-50",TRUE,"50+")} -> 50+
A16: E03496 | B16: Robert Yang | C16: Sr. Analyst | D16: Accounting | E16: Speciality Products | F16: Male | G16: Asian | H16: 31 | I16: 43043 | J16: 97078 | K16: 0 | L16: United States | M16: Austin | N16: 43899 | O16: =J16*K16 -> 0 | P16: =Table1[[#This Row],[Annual Salary]]+Table1[[#This Row],[Bonus Amount]] -> 97078 | Q16: =IF(Table1[[#This Row],[Exit Date]]="", "Active","Exited") -> Exited | R16: =IFERROR(DATEDIF(Table1[[#This Row],[Hire Date]],IF(Table1[[#This Row],[Exit Date]]="",TODAY(),Table1[[#This Row],[Exit Date]]),"Y"),"") -> 2 | S16: {=_xlfn.IFS(Table1[[#This Row],[Age]]<30,"Under 30",Table1[[#This Row],[Age]]<=40,"30-40",Table1[[#This Row],[Age]]<50,"41-50",TRUE,"50+")} -> 30-40
A17: E00549 | B17: Isabella Xi | C17: Vice President | D17: Marketing | E17: Research & Development | F17: Female | G17: Asian | H17: 41 | I17: 41346 | J17: 249270 | K17: 0.3 | L17: United States | M17: Seattle | O17: =J17*K17 -> 74781 | P17: =Table1[[#This Row],[Annual Salary]]+Table1[[#This Row],[Bonus Amount]] -> 324051 | Q17: =IF(Table1[[#This Row],[Exit Date]]="", "Active","Exited") -> Active | R17: =IFERROR(DATEDIF(Table1[[#This Row],[Hire Date]],IF(Table1[[#This Row],[Exit Date]]="",TODAY(),Table1[[#This Row],[Exit Date]]),"Y"),"") -> 13 | S17: {=_xlfn.IFS(Table1[[#This Row],[Age]]<30,"Under 30",Table1[[#This Row],[Age]]<=40,"30-40",Table1[[#This Row],[Age]]<50,"41-50",TRUE,"50+")} -> 41-50
A18: E00163 | B18: Bella Powell | C18: Director | D18: Finance | E18: Research & Development | F18: Female | G18: Black | H18: 65 | I18: 37319 | J18: 175837 | K18: 0.2 | L18: United States | M18: Phoenix | O18: =J18*K18 -> 35167.4 | P18: =Table1[[#This Row],[Annual Salary]]+Table1[[#This Row],[Bonus Amount]] -> 211004.4 | Q18: =IF(Table1[[#This Row],[Exit Date]]="", "Active","Exited") -> Active | R18: =IFERROR(DATEDIF(Table1[[#This Row],[Hire Date]],IF(Table1[[#This Row],[Exit Date]]="",TODAY(),Table1[[#This Row],[Exit Date]]),"Y"),"") -> 24 | S18: {=_xlfn.IFS(Table1[[#This Row],[Age]]<30,"Under 30",Table1[[#This Row],[Age]]<=40,"30-40",Table1[[#This Row],[Age]]<50,"41-50",TRUE,"50+")} -> 50+
A19: E00884 | B19: Camila Silva | C19: Sr. Manger | D19: Marketing | E19: Speciality Products | F19: Female | G19: Latino | H19: 64 | I19: 37956 | J19: 154828 | K19: 0.13 | L19: United States | M19: Seattle | O19: =J19*K19 -> 20127.64 | P19: =Table1[[#This Row],[Annual Salary]]+Table1[[#This Row],[Bonus Amount]] -> 174955.64 | Q19: =IF(Table1[[#This Row],[Exit Date]]="", "Active","Exited") -> Active | R19: =IFERROR(DATEDIF(Table1[[#This Row],[Hire Date]],IF(Table1[[#This Row],[Exit Date]]="",TODAY(),Table1[[#This Row],[Exit Date]]),"Y"),"") -> 22 | S19: {=_xlfn.IFS(Table1[[#This Row],[Age]]<30,"Under 30",Table1[[#This Row],[Age]]<=40,"30-40",Table1[[#This Row],[Age]]<50,"41-50",TRUE,"50+")} -> 50+
A20: E04116 | B20: David Barnes | C20: Director | D20: IT | E20: Corporate | F20: Male | G20: Caucasian | H20: 64 | I20: 41581 | J20: 186503 | K20: 0.24 | L20: United States | M20: Columbus | O20: =J20*K20 -> 44760.72 | P20: =Table1[[#This Row],[Annual Salary]]+Table1[[#This Row],[Bonus Amount]] -> 231263.72 | Q20: =IF(Table1[[#This Row],[Exit Date]]="", "Active","Exited") -> Active | R20: =IFERROR(DATEDIF(Table1[[#This Row],[Hire Date]],IF(Table1[[#This Row],[Exit Date]]="",TODAY(),Table1[[#This Row],[Exit Date]]),"Y"),"") -> 12 | S20: {=_xlfn.IFS(Table1[[#This Row],[Age]]<30,"Under 30",Table1[[#This Row],[Age]]<=40,"30-40",Table1[[#This Row],[Age]]<50,"41-50",TRUE,"50+")} -> 50+
A21: E04625 | B21: Adam Dang | C21: Director | D21: Sales | E21: Research & Development | F21: Male | G21: Asian | H21: 45 | I21: 37446 | J21: 166331 | K21: 0.18 | L21: China | M21: Chongqing | O21: =J21*K21 -> 29939.58 | P21: =Table1[[#This Row],[Annual Salary]]+Table1[[#This Row],[Bonus Amount]] -> 196270.58 | Q21: =IF(Table1[[#This Row],[Exit Date]]="", "Active","Exited") -> Active | R21: =IFERROR(DATEDIF(Table1[[#This Row],[Hire Date]],IF(Table1[[#This Row],[Exit Date]]="",TODAY(),Table1[[#This Row],[Exit Date]]),"Y"),"") -> 23 | S21: {=_xlfn.IFS(Table1[[#This Row],[Age]]<30,"Under 30",Table1[[#This Row],[Age]]<=40,"30-40",Table1[[#This Row],[Age]]<50,"41-50",TRUE,"50+")} -> 41-50
A22: E03680 | B22: Elias Alvarado | C22: Sr. Manger | D22: IT | E22: Manufacturing | F22: Male | G22: Latino | H22: 56 | I22: 40917 | J22: 146140 | K22: 0.1 | L22: Brazil | M22: Manaus | O22: =J22*K22 -> 14614 | P22: =Table1[[#This Row],[Annual Salary]]+Table1[[#This Row],[Bonus Amount]] -> 160754 | Q22: =IF(Table1[[#This Row],[Exit Date]]="", "Active","Exited") -> Active | R22: =IFERROR(DATEDIF(Table1[[#This Row],[Hire Date]],IF(Table1[[#This Row],[Exit Date]]="",TODAY(),Table1[[#This Row],[Exit Date]]),"Y"),"") -> 14 | S22: {=_xlfn.IFS(Table1[[#This Row],[Age]]<30,"Under 30",Table1[[#This Row],[Age]]<=40,"30-40",Table1[[#This Row],[Age]]<50,"41-50",TRUE,"50+")} -> 50+
A23: E04732 | B23: Eva Rivera | C23: Director | D23: Sales | E23: Manufacturing | F23: Female | G23: Latino | H23: 36 | I23: 44288 | J23: 151703 | K23: 0.21 | L23: United States | M23: Miami | O23: =J23*K23 -> 31857.63 | P23: =Table1[[#This Row],[Annual Salary]]+Table1[[#This Row],[Bonus Amount]] -> 183560.63 | Q23: =IF(Table1[[#This Row],[Exit Date]]="", "Active","Exited") -> Active | R23: =IFERROR(DATEDIF(Table1[[#This Row],[Hire Date]],IF(Table1[[#This Row],[Exit Date]]="",TODAY(),Table1[[#This Row],[Exit Date]]),"Y"),"") -> 4 | S23: {=_xlfn.IFS(Table1[[#This Row],[Age]]<30,"Under 30",Table1[[#This Row],[Age]]<=40,"30-40",Table1[[#This Row],[Age]]<50,"41-50",TRUE,"50+")} -> 30-40
A24: E03484 | B24: Logan Rivera | C24: Director | D24: IT | E24: Research & Development | F24: Male | G24: Latino | H24: 59 | I24: 37400 | J24: 172787 | K24: 0.28 | L24: Brazil | M24: Rio de Janerio | O24: =J24*K24 -> 48380.36 | P24: =Table1[[#This Row],[Annual Salary]]+Table1[[#This Row],[Bonus Amount]] -> 221167.36 | Q24: =IF(Table1[[#This Row],[Exit Date]]="", "Active","Exited") -> Active | R24: =IFERROR(DATEDIF(Table1[[#This Row],[Hire Date]],IF(Table1[[#This Row],[Exit Date]]="",TODAY(),Table1[[#This Row],[Exit Date]]),"Y"),"") -> 23 | S24: {=_xlfn.IFS(Table1[[#This Row],[Age]]<30,"Under 30",Table1[[#This Row],[Age]]<=40,"30-40",Table1[[#This Row],[Age]]<50,"41-50",TRUE,"50+")} -> 50+
A25: E00671 | B25: Leonardo Dixon | C25: Analyst | D25: Sales | E25: Speciality Products | F25: Male | G25: Caucasian | H25: 37 | I25: 43713 | J25: 49998 | K25: 0 | L25: United States | M25: Seattle | O25: =J25*K25 -> 0 | P25: =Table1[[#This Row],[Annual Salary]]+Table1[[#This Row],[Bonus Amount]] -> 49998 | Q25: =IF(Table1[[#This Row],[Exit Date]]="", "Active","Exited") -> Active | R25: =IFERROR(DATEDIF(Table1[[#This Row],[Hire Date]],IF(Table1[[#This Row],[Exit Date]]="",TODAY(),Table1[[#This Row],[Exit Date]]),"Y"),"") -> 6 | S25: {=_xlfn.IFS(Table1[[#This Row],[Age]]<30,"Under 30",Table1[[#This Row],[Age]]<=40,"30-40",Table1[[#This Row],[Age]]<50,"41-50",TRUE,"50+")} -> 30-40
A26: E02071 | B26: Mateo Her | C26: Vice President | D26: Sales | E26: Speciality Products | F26: Male | G26: Asian | H26: 44 | I26: 41700 | J26: 207172 | K26: 0.31 | L26: China | M26: Chongqing | O26: =J26*K26 -> 64223.32 | P26: =Table1[[#This Row],[Annual Salary]]+Table1[[#This Row],[Bonus Amount]] -> 271395.32 | Q26: =IF(Table1[[#This Row],[Exit Date]]="", "Active","Exited") -> Active | R26: =IFERROR(DATEDIF(Table1[[#This Row],[Hire Date]],IF(Table1[[#This Row],[Exit Date]]="",TODAY(),Table1[[#This Row],[Exit Date]]),"Y"),"") -> 12 | S26: {=_xlfn.IFS(Table1[[#This Row],[Age]]<30,"Under 30",Table1[[#This Row],[Age]]<=40,"30-40",Table1[[#This Row],[Age]]<50,"41-50",TRUE,"50+")} -> 41-50
A27: E02206 | B27: Jose Henderson | C27: Director | D27: Human Resources | E27: Speciality Products | F27: Male | G27: Black | H27: 41 | I27: 42111 | J27: 152239 | K27: 0.23 | L27: United States | M27: Columbus | O27: =J27*K27 -> 35014.97 | P27: =Table1[[#This Row],[Annual Salary]]+Table1[[#This Row],[Bonus Amount]] -> 187253.97 | Q27: =IF(Table1[[#This Row],[Exit Date]]="", "Active","Exited") -> Active | R27: =IFERROR(DATEDIF(Table1[[#This Row],[Hire Date]],IF(Table1[[#This Row],[Exit Date]]="",TODAY(),Table1[[#This Row],[Exit Date]]),"Y"),"") -> 10 | S27: {=_xlfn.IFS(Table1[[#This Row],[Age]]<30,"Under 30",Table1[[#This Row],[Age]]<=40,"30-40",Table1[[#This Row],[Age]]<50,"41-50",TRUE,"50+")} -> 41-50
A28: E04545 | B28: Abigail Mejia | C28: Quality Engineer | D28: Engineering | E28: Corporate | F28: Female | G28: Latino | H28: 56 | I28: 38388 | J28: 98581 | K28: 0 | L28: Brazil | M28: Rio de Janerio | O28: =J28*K28 -> 0 | P28: =Table1[[#This Row],[Annual Salary]]+Table1[[#This Row],[Bonus Amount]] -> 98581 | Q28: =IF(Table1[[#This Row],[Exit Date]]="", "Active","Exited") -> Active | R28: =IFERROR(DATEDIF(Table1[[#This Row],[Hire Date]],IF(Table1[[#This Row],[Exit Date]]="",TODAY(),Table1[[#This Row],[Exit Date]]),"Y"),"") -> 21 | S28: {=_xlfn.IFS(Table1[[#This Row],[Age]]<30,"Under 30",Table1[[#This Row],[Age]]<=40,"30-40",Table1[[#This Row],[Age]]<50,"41-50",TRUE,"50+")} -> 50+
... A41: E01417 | B41: Leah Pena | C41: Enterprise Architect | D41: IT | E41: Corporate | F41: Female | G41: Latino | H41: 57 | I41: 34337 | J41: 82872 | K41: 0 | L41: Brazil | M41: Manaus | O41: =J41*K41 -> 0 | P41: =Table1[[#This Row],[Annual Salary]]+Table1[[#This Row],[Bonus Amount]] -> 82872 | Q41: =IF(Table1[[#This Row],[Exit Date]]="", "Active","Exited") -> Active | R41: =IFERROR(DATEDIF(Table1[[#This Row],[Hire Date]],IF(Table1[[#This Row],[Exit Date]]="",TODAY(),Table1[[#This Row],[Exit Date]]),"Y"),"") -> 32 | S41: {=_xlfn.IFS(Table1[[#This Row],[Age]]<30,"Under 30",Table1[[#This Row],[Age]]<=40,"30-40",Table1[[#This Row],[Age]]<50,"41-50",TRUE,"50+")} -> 50+
A42: E01754 | B42: Owen Lam | C42: Sr. Business Partner | D42: Human Resources | E42: Speciality Products | F42: Male | G42: Asian | H42: 30 | I42: 42884 | J42: 86317 | K42: 0 | L42: China | M42: Chengdu | N42: 42932 | O42: =J42*K42 -> 0 | P42: =Table1[[#This Row],[Annual Salary]]+Table1[[#This Row],[Bonus Amount]] -> 86317 | Q42: =IF(Table1[[#This Row],[Exit Date]]="", "Active","Exited") -> Exited | R42: =IFERROR(DATEDIF(Table1[[#This Row],[Hire Date]],IF(Table1[[#This Row],[Exit Date]]="",TODAY(),Table1[[#This Row],[Exit Date]]),"Y"),"") -> 0 | S42: {=_xlfn.IFS(Table1[[#This Row],[Age]]<30,"Under 30",Table1[[#This Row],[Age]]<=40,"30-40",Table1[[#This Row],[Age]]<50,"41-50",TRUE,"50+")} -> 30-40
A43: E03749 | B43: Kennedy Foster | C43: Manager | D43: Marketing | E43: Speciality Products | F43: Female | G43: Caucasian | H43: 53 | I43: 41601 | J43: 113135 | K43: 0.05 | L43: United States | M43: Austin | O43: =J43*K43 -> 5656.75 | P43: =Table1[[#This Row],[Annual Salary]]+Table1[[#This Row],[Bonus Amount]] -> 118791.75 | Q43: =IF(Table1[[#This Row],[Exit Date]]="", "Active","Exited") -> Active | R43: =IFERROR(DATEDIF(Table1[[#This Row],[Hire Date]],IF(Table1[[#This Row],[Exit Date]]="",TODAY(),Table1[[#This Row],[Exit Date]]),"Y"),"") -> 12 | S43: {=_xlfn.IFS(Table1[[#This Row],[Age]]<30,"Under 30",Table1[[#This Row],[Age]]<=40,"30-40",Table1[[#This Row],[Age]]<50,"41-50",TRUE,"50+")} -> 50+
A44: E03574 | B44: John Moore | C44: Vice President | D44: IT | E44: Speciality Products | F44: Male | G44: Caucasian | H44: 52 | I44: 38664 | J44: 199808 | K44: 0.32 | L44: United States | M44: Seattle | O44: =J44*K44 -> 63938.56 | P44: =Table1[[#This Row],[Annual Salary]]+Table1[[#This Row],[Bonus Amount]] -> 263746.56 | Q44: =IF(Table1[[#This Row],[Exit Date]]="", "Active","Exited") -> Active | R44: =IFERROR(DATEDIF(Table1[[#This Row],[Hire Date]],IF(Table1[[#This Row],[Exit Date]]="",TODAY(),Table1[[#This Row],[Exit Date]]),"Y"),"") -> 20 | S44: {=_xlfn.IFS(Table1[[#This Row],[Age]]<30,"Under 30",Table1[[#This Row],[Age]]<=40,"30-40",Table1[[#This Row],[Age]]<50,"41-50",TRUE,"50+")} -> 50+
A45: E04600 | B45: William Vu | C45: Account Representative | D45: Sales | E45: Speciality Products | F45: Male | G45: Asian | H45: 37 | I45: 41592 | J45: 56037 | K45: 0 | L45: China | M45: Shanghai | O45: =J45*K45 -> 0 | P45: =Table1[[#This Row],[Annual Salary]]+Table1[[#This Row],[Bonus Amount]] -> 56037 | Q45: =IF(Table1[[#This Row],[Exit Date]]="", "Active","Exited") -> Active | R45: =IFERROR(DATEDIF(Table1[[#This Row],[Hire Date]],IF(Table1[[#This Row],[Exit Date]]="",TODAY(),Table1[[#This Row],[Exit Date]]),"Y"),"") -> 12 | S45: {=_xlfn.IFS(Table1[[#This Row],[Age]]<30,"Under 30",Table1[[#This Row],[Age]]<=40,"30-40",Table1[[#This Row],[Age]]<50,"41-50",TRUE,"50+")} -> 30-40
A46: E00586 | B46: Sadie Washington | C46: Sr. Manger | D46: Marketing | E46: Research & Development | F46: Female | G46: Caucasian | H46: 29 | I46: 43609 | J46: 122350 | K46: 0.12 | L46: United States | M46: Phoenix | O46: =J46*K46 -> 14682 | P46: =Table1[[#This Row],[Annual Salary]]+Table1[[#This Row],[Bonus Amount]] -> 137032 | Q46: =IF(Table1[[#This Row],[Exit Date]]="", "Active","Exited") -> Active | R46: =IFERROR(DATEDIF(Table1[[#This Row],[Hire Date]],IF(Table1[[#This Row],[Exit Date]]="",TODAY(),Table1[[#This Row],[Exit Date]]),"Y"),"") -> 6 | S46: {=_xlfn.IFS(Table1[[#This Row],[Age]]<30,"Under 30",Table1[[#This Row],[Age]]<=40,"30-40",Table1[[#This Row],[Age]]<50,"41-50",TRUE,"50+")} -> Under 30
A47: E03538 | B47: Gabriel Holmes | C47: Enterprise Architect | D47: IT | E47: Research & Development | F47: Male | G47: Caucasian | H47: 40 | I47: 40486 | J47: 92952 | K47: 0 | L47: United States | M47: Seattle | O47: =J47*K47 -> 0 | P47: =Table1[[#This Row],[Annual Salary]]+Table1[[#This Row],[Bonus Amount]] -> 92952 | Q47: =IF(Table1[[#This Row],[Exit Date]]="", "Active","Exited") -> Active | R47: =IFERROR(DATEDIF(Table1[[#This Row],[Hire Date]],IF(Table1[[#This Row],[Exit Date]]="",TODAY(),Table1[[#This Row],[Exit Date]]),"Y"),"") -> 15 | S47: {=_xlfn.IFS(Table1[[#This Row],[Age]]<30,"Under 30",Table1[[#This Row],[Age]]<=40,"30-40",Table1[[#This Row],[Age]]<50,"41-50",TRUE,"50+")} -> 30-40
A48: E02185 | B48: Wyatt Rojas | C48: Computer Systems Manager | D48: IT | E48: Corporate | F48: Male | G48: Latino | H48: 32 | I48: 41353 | J48: 79921 | K48: 0.05 | L48: United States | M48: Austin | O48: =J48*K48 -> 3996.05 | P48: =Table1[[#This Row],[Annual Salary]]+Table1[[#This Row],[Bonus Amount]] -> 83917.05 | Q48: =IF(Table1[[#This Row],[Exit Date]]="", "Active","Exited") -> Active | R48: =IFERROR(DATEDIF(Table1[[#This Row],[Hire Date]],IF(Table1[[#This Row],[Exit Date]]="",TODAY(),Table1[[#This Row],[Exit Date]]),"Y"),"") -> 13 | S48: {=_xlfn.IFS(Table1[[#This Row],[Age]]<30,"Under 30",Table1[[#This Row],[Age]]<=40,"30-40",Table1[[#This Row],[Age]]<50,"41-50",TRUE,"50+")} -> 30-40
A49: E03830 | B49: Eva Coleman | C49: Director | D49: IT | E49: Research & Development | F49: Female | G49: Black | H49: 37 | I49: 40076 | J49: 167199 | K49: 0.2 | L49: United States | M49: Seattle | O49: =J49*K49 -> 33439.8 | P49: =Table1[[#This Row],[Annual Salary]]+Table1[[#This Row],[Bonus Amount]] -> 200638.8 | Q49: =IF(Table1[[#This Row],[Exit Date]]="", "Active","Exited") -> Active | R49: =IFERROR(DATEDIF(Table1[[#This Row],[Hire Date]],IF(Table1[[#This Row],[Exit Date]]="",TODAY(),Table1[[#This Row],[Exit Date]]),"Y"),"") -> 16 | S49: {=_xlfn.IFS(Table1[[#This Row],[Age]]<30,"Under 30",Table1[[#This Row],[Age]]<=40,"30-40",Table1[[#This Row],[Age]]<50,"41-50",TRUE,"50+")} -> 30-40
A50: E03720 | B50: Dominic Clark | C50: Quality Engineer | D50: Engineering | E50: Research & Development | F50: Male | G50: Caucasian | H50: 52 | I50: 41199 | J50: 71476 | K50: 0 | L50: United States | M50: Phoenix | O50: =J50*K50 -> 0 | P50: =Table1[[#This Row],[Annual Salary]]+Table1[[#This Row],[Bonus Amount]] -> 71476 | Q50: =IF(Table1[[#This Row],[Exit Date]]="", "Active","Exited") -> Active | R50: =IFERROR(DATEDIF(Table1[[#This Row],[Hire Date]],IF(Table1[[#This Row],[Exit Date]]="",TODAY(),Table1[[#This Row],[Exit Date]]),"Y"),"") -> 13 | S50: {=_xlfn.IFS(Table1[[#This Row],[Age]]<30,"Under 30",Table1[[#This Row],[Age]]<=40,"30-40",Table1[[#This Row],[Age]]<50,"41-50",TRUE,"50+")} -> 50+
A51: E03025 | B51: Lucy Alexander | C51: Director | D51: Engineering | E51: Manufacturing | F51: Female | G51: Caucasian | H51: 45 | I51: 41941 | J51: 189420 | K51: 0.2 | L51: United States | M51: Seattle | O51: =J51*K51 -> 37884 | P51: =Table1[[#This Row],[Annual Salary]]+Table1[[#This Row],[Bonus Amount]] -> 227304 | Q51: =IF(Table1[[#This Row],[Exit Date]]="", "Active","Exited") -> Active | R51: =IFERROR(DATEDIF(Table1[[#This Row],[Hire Date]],IF(Table1[[#This Row],[Exit Date]]="",TODAY(),Table1[[#This Row],[Exit Date]]),"Y"),"") -> 11 | S51: {=_xlfn.IFS(Table1[[#This Row],[Age]]<30,"Under 30",Table1[[#This Row],[Age]]<=40,"30-40",Table1[[#This Row],[Age]]<50,"41-50",TRUE,"50+")} -> 41-50
A52: E04917 | B52: Everleigh Washington | C52: HRIS Analyst | D52: Human Resources | E52: Research & Development | F52: Female | G52: Caucasian | H52: 64 | I52: 37184 | J52: 64057 | K52: 0 | L52: United States | M52: Phoenix | O52: =J52*K52 -> 0 | P52: =Table1[[#This Row],[Annual Salary]]+Table1[[#This Row],[Bonus Amount]] -> 64057 | Q52: =IF(Table1[[#This Row],[Exit Date]]="", "Active","Exited") -> Active | R52: =IFERROR(DATEDIF(Table1[[#This Row],[Hire Date]],IF(Table1[[#This Row],[Exit Date]]="",TODAY(),Table1[[#This Row],[Exit Date]]),"Y"),"") -> 24 | S52: {=_xlfn.IFS(Table1[[#This Row],[Age]]<30,"Under 30",Table1[[#This Row],[Age]]<=40,"30-40",Table1[[#This Row],[Age]]<50,"41-50",TRUE,"50+")} -> 50+
...

Sheet KPI_Helper
A1: Total Employees | B1: Total Salary Cost | C1: Total Bonus Cost | D1: Total Compensation of Employees | E1: Avg Age | F1: Avg Tenure
A2: 1000 | B2: 113217365 | C2: 15873801 | D2: 1.2909117e+08 | E2: 44.382 | F2: 12.524 | K2: Row Labels | L2: Employee Count
K3: Active | L3: 915
K4: Exited | L4: 85
K5: Grand Total | L5: 1000
A13: Row Labels | B13: Average of Tenure
A14: Accounting | B14: 11.3125
A15: Engineering | B15: 12.886076
A16: Finance | B16: 12.65
A17: Human Resources | B17: 12.56
A18: IT | B18: 13.008299
A19: Marketing | B19: 11.541667
A20: Sales | B20: 12.814286
A21: Grand Total | B21: 12.524

Sheet DASHBOARD
B2: HR Analytics Dashboard
B4: =GETPIVOTDATA("Total Employees",KPI_Helper!A1) -> 1000 | E4: =GETPIVOTDATA("EEID",KPI_Helper!K2,"Employee Status","Active") -> 915 | H4: =GETPIVOTDATA("EEID",KPI_Helper!$K$2,"Employee Status","Exited") -> 85 | K4: =GETPIVOTDATA("Avg Tenure",KPI_Helper!F1) -> 12.524 | N4: =H4/B4 -> 0.085
B5: Total Employees | E5: Active Employees | H5: Exited Employees | K5: Avg Tenure | N5: Attrition Rate %
B7: =GETPIVOTDATA("Total Salary Cost",KPI_Helper!B1) -> 113217365 | E7: =GETPIVOTDATA("Total Bonus Cost",KPI_Helper!C2) -> 15873801 | H7: =GETPIVOTDATA("Total Compensation of Employees",KPI_Helper!D2) -> 1.2909117e+08 | K7: =GETPIVOTDATA("Avg Age",KPI_Helper!E1) -> 44.382 | N7: =E4/B4 -> 0.915
B8: Total Salary Cost | E8: Total Bonus Cost | H8: Total Compensation | K8: Avg Age | N8: Retention Rate

Sheet Salary_Helper
A1: Row Labels | B1: Average of Annual Salary
A2: Vice President | B2: 222195.17
A3: Director | B3: 171633.85
A4: Sr. Manger | B4: 141067.76
A5: Manager | B5: 113275.68
A6: Engineering Manager | B6: 101853.8
A7: Operations Engineer | B7: 101135.25
A8: Controls Engineer | B8: 99626.133
A9: Automation Engineer | B9: 95106.857
A10: Cloud Infrastructure Architect | B10: 86961.333
A11: Sr. Analyst | B11: 86402.957
A12: Sr. Business Partner | B12: 85035.353
A13: Sr. Account Representative | B13: 84808.222
... A35: Grand Total | B35: 113217.37

Sheet Dept_Headcount_Helper
A1: Row Labels | B1: Count of EEID
A2: Accounting | B2: 96
A3: Finance | B3: 120
A4: Marketing | B4: 120
A5: Human Resources | B5: 125
A6: Sales | B6: 140
A7: Engineering | B7: 158
A8: IT | B8: 241
A9: Grand Total | B9: 1000

Sheet Gender_Helper
A1: Row Labels | B1: Count of EEID
A2: Female | B2: 518
A3: Male | B3: 482
A4: Grand Total | B4: 1000

Sheet Attrition_Helper
A1: Count of EEID | B1: Column Labels
A2: Row Labels | B2: Active | C2: Exited | D2: Grand Total
A3: Accounting | B3: 89 | C3: 7 | D3: 96
A4: Engineering | B4: 141 | C4: 17 | D4: 158
A5: Finance | B5: 111 | C5: 9 | D5: 120
A6: Human Resources | B6: 114 | C6: 11 | D6: 125
A7: IT | B7: 225 | C7: 16 | D7: 241
A8: Marketing | B8: 105 | C8: 15 | D8: 120
A9: Sales | B9: 130 | C9: 10 | D9: 140
A10: Grand Total | B10: 915 | C10: 85 | D10: 1000

Sheet Country_Helper
A2: Row Labels | B2: Count of EEID
A3: United States | B3: 643
A4: China | B4: 218
A5: Brazil | B5: 139
A6: Grand Total | B6: 1000
